<?xml version="1.0" encoding="utf-8"?>
<!-- This URDF was automatically created by SolidWorks to URDF Exporter! Originally created by Stephen Brawner (brawner@gmail.com) 
     Commit Version: 1.6.0-4-g7f85cfe  Build Version: 1.6.7995.38578
     For more information, please see http://wiki.ros.org/sw_urdf_exporter -->
<robot
  name="car_model">

  <!-- base_link-->
  <link
    name="base_link">
    <inertial>
      <origin
        xyz="2.77555756156289E-17 0 0.057"
        rpy="0 0 0" />
      <mass
        value="6.075" />
      <inertia
        ixx="0.01265625"
        ixy="-8.43075609324729E-19"
        ixz="-4.83012067842292E-19"
        iyy="0.046828125"
        iyz="1.82959116606929E-19"
        izz="0.0569531249999999" />
    </inertial>
    <visual>
      <origin
        xyz="0 0 0"
        rpy="0 0 0" />
      <geometry>
        <mesh
          filename="package://car_model/meshes/base_link.STL" />
      </geometry>
      <material
        name="">
        <color
          rgba="0.898039215686275 0.917647058823529 0.929411764705882 1" />
      </material>
    </visual>
    <collision>
      <origin
        xyz="0 0 0"
        rpy="0 0 0" />
      <geometry>
        <mesh
          filename="package://car_model/meshes/base_link.STL" />
      </geometry>
    </collision>
  </link>

  <!-- yaw_link-->
  <link
    name="yaw_link">
    <inertial>
      <origin
        xyz="0.0537035888519797 2.77555756156289E-17 0.0712964111480203"
        rpy="0 0 0" />
      <mass
        value="0.126568478674109" />
      <inertia
        ixx="0.000221320169573416"
        ixy="1.48946522374663E-20"
        ixz="-0.000162758542794411"
        iyy="0.000414478500991876"
        iyz="1.37587819480297E-21"
        izz="0.000221320169573416" />
    </inertial>
    <visual>
      <origin
        xyz="0 0 0"
        rpy="0 0 0" />
      <geometry>
        <mesh
          filename="package://car_model/meshes/yaw_link.STL" />
      </geometry>
      <material
        name="">
        <color
          rgba="1 1 1 1" />
      </material>
    </visual>
    <collision>
      <origin
        xyz="0 0 0"
        rpy="0 0 0" />
      <geometry>
        <mesh
          filename="package://car_model/meshes/yaw_link.STL" />
      </geometry>
    </collision>
  </link>
  <joint
    name="yaw_joint"
    type="revolute">
    <origin
      xyz="0 0 0.057"
      rpy="0 0 0" />
    <parent
      link="base_link" />
    <child
      link="yaw_link" />
    <axis
      xyz="0 0 1" />
    <limit
      lower="-1.5708"
      upper="1.5708"
      effort="0"
      velocity="0" />
  </joint>

  <!-- roll_link-->
  <link
    name="roll_link">
    <inertial>
      <origin
        xyz="0 -0.0512022585563426 0.038194744084013"
        rpy="0 0 0" />
      <mass
        value="0.118408478674109" />
      <inertia
        ixx="0.000321578851110391"
        ixy="-3.97716332051993E-21"
        ixz="-1.40410282009952E-21"
        iyy="0.000139911584896368"
        iyz="0.000125539633856422"
        izz="0.000209285104368979" />
    </inertial>
    <visual>
      <origin
        xyz="0 0 0"
        rpy="0 0 0" />
      <geometry>
        <mesh
          filename="package://car_model/meshes/roll_link.STL" />
      </geometry>
      <material
        name="">
        <color
          rgba="1 1 1 1" />
      </material>
    </visual>
    <collision>
      <origin
        xyz="0 0 0"
        rpy="0 0 0" />
      <geometry>
        <mesh
          filename="package://car_model/meshes/roll_link.STL" />
      </geometry>
    </collision>
  </link>
  <joint
    name="roll_joint"
    type="revolute">
    <origin
      xyz="0.08 0 0.125"
      rpy="3.14159265358979 1.5707963267949 0" />
    <parent
      link="yaw_link" />
    <child
      link="roll_link" />
    <axis
      xyz="0 0 1" />
    <limit
      lower="-1.5708"
      upper="1.5708"
      effort="0"
      velocity="0" />
  </joint>

  <!-- pitch_link-->
  <link
    name="pitch_link">
    <inertial>
      <origin
        xyz="-5.55111512312578E-17 0.00408688138606272 0.0279674424503152"
        rpy="0 0 0" />
      <mass
        value="0.0677397308399315" />
      <inertia
        ixx="5.24830874281838E-05"
        ixy="-5.05875770299915E-22"
        ixz="4.8065064995983E-21"
        iyy="5.08193710319635E-05"
        iyz="-7.19691411372773E-06"
        izz="1.59732208507003E-05" />
    </inertial>
    <visual>
      <origin
        xyz="0 0 0"
        rpy="0 0 0" />
      <geometry>
        <mesh
          filename="package://car_model/meshes/pitch_link.STL" />
      </geometry>
      <material
        name="">
        <color
          rgba="1 1 1 1" />
      </material>
    </visual>
    <collision>
      <origin
        xyz="0 0 0"
        rpy="0 0 0" />
      <geometry>
        <mesh
          filename="package://car_model/meshes/pitch_link.STL" />
      </geometry>
    </collision>
  </link>
  <joint
    name="pitch_joint"
    type="revolute">
    <origin
      xyz="0 -0.08 0.0799999999999999"
      rpy="-1.5707963267949 0 0" />
    <parent
      link="roll_link" />
    <child
      link="pitch_link" />
    <axis
      xyz="0 0 1" />
    <limit
      lower="-1.5708"
      upper="1.5708"
      effort="0"
      velocity="0" />
  </joint>

  <!-- w1_link -->
  <link
    name="w1_link">
    <inertial>
      <origin
        xyz="-1.73472347597681E-18 0 5.55111512312578E-17"
        rpy="0 0 0" />
      <mass
        value="0.258835255001734" />
      <inertia
        ixx="0.000194189872502159"
        ixy="5.56337966357173E-36"
        ixz="1.49875529729842E-36"
        iyy="0.000194189872502159"
        iyz="-7.6736271221679E-37"
        izz="0.000353817262685931" />
    </inertial>
    <visual>
      <origin
        xyz="0 0 0"
        rpy="0 0 0" />
      <geometry>
        <mesh
          filename="package://car_model/meshes/w1_link.STL" />
      </geometry>
      <material
        name="">
        <color
          rgba="1 1 1 1" />
      </material>
    </visual>
    <collision>
      <origin
        xyz="0 0 0"
        rpy="0 0 0" />
      <geometry>
        <mesh
          filename="package://car_model/meshes/w1_link.STL" />
      </geometry>
    </collision>
  </link>
  <joint
    name="w1_joint"
    type="continuous">
    <origin
      xyz="-0.125 -0.09 0.057"
      rpy="1.5707963267949 0 0" />
    <parent
      link="base_link" />
    <child
      link="w1_link" />
    <axis
      xyz="0 0 -1" />
  </joint>

  <!-- w2_link -->
  <link
    name="w2_link">
    <inertial>
      <origin
        xyz="0 0 5.55111512312578E-17"
        rpy="0 0 0" />
      <mass
        value="0.258835255001734" />
      <inertia
        ixx="0.000194189872502159"
        ixy="9.59203390270988E-37"
        ixz="1.72794721239877E-21"
        iyy="0.000194189872502159"
        iyz="8.31976319669812E-53"
        izz="0.000353817262685931" />
    </inertial>
    <visual>
      <origin
        xyz="0 0 0"
        rpy="0 0 0" />
      <geometry>
        <mesh
          filename="package://car_model/meshes/w2_link.STL" />
      </geometry>
      <material
        name="">
        <color
          rgba="1 1 1 1" />
      </material>
    </visual>
    <collision>
      <origin
        xyz="0 0 0"
        rpy="0 0 0" />
      <geometry>
        <mesh
          filename="package://car_model/meshes/w2_link.STL" />
      </geometry>
    </collision>
  </link>
  <joint
    name="w2_joint"
    type="continuous">
    <origin
      xyz="0.125 -0.09 0.057"
      rpy="1.5707963267949 0 0" />
    <parent
      link="base_link" />
    <child
      link="w2_link" />
    <axis
      xyz="0 0 1" />
  </joint>

  <!-- w3_link -->
  <link
    name="w3_link">
    <inertial>
      <origin
        xyz="0 2.77555756156289E-17 1.38777878078145E-17"
        rpy="0 0 0" />
      <mass
        value="0.258835255001734" />
      <inertia
        ixx="0.000194189872502159"
        ixy="9.59203390270988E-37"
        ixz="2.61897774471385E-36"
        iyy="0.000194189872502159"
        iyz="1.59780146010327E-52"
        izz="0.000353817262685931" />
    </inertial>
    <visual>
      <origin
        xyz="0 0 0"
        rpy="0 0 0" />
      <geometry>
        <mesh
          filename="package://car_model/meshes/w3_link.STL" />
      </geometry>
      <material
        name="">
        <color
          rgba="1 1 1 1" />
      </material>
    </visual>
    <collision>
      <origin
        xyz="0 0 0"
        rpy="0 0 0" />
      <geometry>
        <mesh
          filename="package://car_model/meshes/w3_link.STL" />
      </geometry>
    </collision>
  </link>
  <joint
    name="w3_joint"
    type="continuous">
    <origin
      xyz="0.125 0.09 0.057"
      rpy="1.5707963267949 0 0" />
    <parent
      link="base_link" />
    <child
      link="w3_link" />
    <axis
      xyz="0 0 1" />
  </joint>

  <!-- w4_link -->
  <link
    name="w4_link">
    <inertial>
      <origin
        xyz="-1.73472347597681E-18 0 2.77555756156289E-17"
        rpy="0 0 0" />
      <mass
        value="0.258835255001734" />
      <inertia
        ixx="0.000194189872502159"
        ixy="6.33074237578851E-36"
        ixz="1.72794721239877E-21"
        iyy="0.000194189872502159"
        iyz="-1.15104406832518E-36"
        izz="0.000353817262685931" />
    </inertial>
    <visual>
      <origin
        xyz="0 0 0"
        rpy="0 0 0" />
      <geometry>
        <mesh
          filename="package://car_model/meshes/w4_link.STL" />
      </geometry>
      <material
        name="">
        <color
          rgba="1 1 1 1" />
      </material>
    </visual>
    <collision>
      <origin
        xyz="0 0 0"
        rpy="0 0 0" />
      <geometry>
        <mesh
          filename="package://car_model/meshes/w4_link.STL" />
      </geometry>
    </collision>
  </link>
  <joint
    name="w4_joint"
    type="continuous">
    <origin
      xyz="-0.125 0.09 0.057"
      rpy="1.5707963267949 0 0" />
    <parent
      link="base_link" />
    <child
      link="w4_link" />
    <axis
      xyz="0 0 -1" />
  </joint>

  <gazebo reference="w1_link">
    <mu1>1</mu1>
    <mu2>1</mu2>
  </gazebo> 
  <gazebo reference="w2_link">
    <mu1>0.01</mu1>
    <mu2>0.01</mu2>
  </gazebo> 
  <gazebo reference="w3_link">
    <mu1>0.01</mu1>
    <mu2>0.01</mu2>
  </gazebo> 
  <gazebo reference="w4_link">
    <mu1>1</mu1>
    <mu2>1</mu2>
  </gazebo> 

  <transmission name="tran1">
    <type>transmission_interface/SimpleTransmission</type>
    <joint name="w1_joint">
      <hardwareInterface>VelocityJointInterface</hardwareInterface>
    </joint>
    <actuator name="motor1">
      <hardwareInterface>VelocityJointInterface</hardwareInterface>
      <mechanicalReduction>1</mechanicalReduction>
    </actuator>
  </transmission>

  <transmission name="tran2">
    <type>transmission_interface/SimpleTransmission</type>
    <joint name="w4_joint">
      <hardwareInterface>VelocityJointInterface</hardwareInterface>
    </joint>
    <actuator name="motor2">
      <hardwareInterface>VelocityJointInterface</hardwareInterface>
      <mechanicalReduction>1</mechanicalReduction>
    </actuator>
  </transmission>

  <transmission name="tran3">
    <type>transmission_interface/SimpleTransmission</type>
    <joint name="yaw_joint">
      <hardwareInterface>EffortJointInterface</hardwareInterface>
    </joint>
    <actuator name="motor3">
      <hardwareInterface>EffortJointInterface</hardwareInterface>
      <mechanicalReduction>1</mechanicalReduction>
    </actuator>
  </transmission>

  

  <gazebo>
    <plugin name="gazebo_ros_control" filename="libgazebo_ros_control.so">
      <robotNamespace> /car_model </robotNamespace>
      <robotSimType>gazebo_ros_control/DefaultRobotHWSim</robotSimType>
    </plugin>
  </gazebo>
</robot>
